Workbook

Sheet SUMMARY
B1: COLLECTION SUMMARY
B3: Activity | C3: Amount Collectable | D3: Amount Collected | E3: Collectable
B4: SBO : 400 | C4: =279*400 -> 111600 | D4: =SBO!C3 -> 3600 | E4: =C4-D4 -> 108000
B5: AParty | C5: =279*1000 -> 279000
B6: TShirt
B7: Intrams
B8: Total | C8: =sum(C4:C7) -> 390600 | D8: =sum(D4:D7) -> 3600 | E8: =sum(E4:E7) -> 108000
B10: Total No. of Students : 279
B14: Activity | C14: Amount
B15: SBO : 400 | C15: =Fines!E284 -> 108000
B16: AParty | C16: =Fines!F284 -> 0
B17: TShirt | C17: =Fines!G284 -> 0
B18: Intrams | C18: =Fines!H284 -> 0
B19: Attendance | C19: =Fines!I284 -> 0
B20: Total | C20: =sum(C15:C19) -> 108000

Sheet SBO
A1: SBO FEE COLLECTION (279 X 400 = 111,600)
B3: Collection Amount | C3: =SUM(E6:E284) -> 3600 | E3: Account Collectable : | G3: =(279*400)-C3 -> 108000
A5: SL # | B5: STUDENT NAME | C5: COURSE/Major | D5: YEAR | E5: Amount | F5: Date Paid | G5: Payment Type | H5: OR#
A6: 1 | B6: SACAL, GERELYN KAWE T. | C6: BLIS | D6: 1
A7: 2 | B7: VILELA, SAMANTHA KRIS P. | C7: BLIS | D7: 1
A8: 3 | B8: MORENO, NICOLE ROANNIE D. | C8: BLIS | D8: 1
A9: 4 | B9: YAMSON, HOPE GRACE I. | C9: BLIS | D9: 1
A10: 5 | B10: TEJANO, ERIKA MAE A. | C10: BLIS | D10: 1
A11: 6 | B11: DE-ERIT, ROSE MAE J. | C11: BLIS | D11: 1
A12: 7 | B12: ADAJAR, RHEA JEAN M. | C12: BLIS-ACADEMIC TRACK | D12: 1
A13: 8 | B13: OMANDAM, ANDRE JOSHUA P. | C13: BSIT-CISCO | D13: 1
A14: 9 | B14: MAGBOO, RALPH JOSHUA P. | C14: BSIT-CISCO | D14: 1
A15: 10 | B15: NAVARRO, MIKKO S. | C15: BSIT-CISCO | D15: 1
A16: 11 | B16: CANDIA, SOPHIA CHRISTIANA A. | C16: BSIT-CISCO | D16: 1
A17: 12 | B17: LALA, LANCE NICHOLAS | C17: BSIT-CISCO | D17: 1
... A21: 16 | B21: Acero, James B. | C21: BSIT-CISCO | D21: 1
A22: 17 | B22: Nabos, Mariane T. | C22: BSIT-CISCO | D22: 1 | E22: 400 | F22: 45799 | G22: CASH | H22: 5
A23: 18 | B23: MALAYA, JHOZEL M. | C23: BSIT-CISCO | D23: 1
A24: 19 | B24: CAGALITAN, ALLYXZA SOPHIA K. | C24: BSIT-CISCO | D24: 1
A25: 20 | B25: UBA, KEN MARK C. | C25: BSIT-CISCO | D25: 1
A26: 21 | B26: BALATAYO, FREDERICK JAMES S. | C26: BSIT-CISCO | D26: 1
A27: 22 | B27: VALDEZ, PRINCESS MARIE J. | C27: BSIT-CISCO | D27: 1
A28: 23 | B28: MAGUIDALA, CARIM S. | C28: BSIT-CISCO | D28: 1
A29: 24 | B29: AGUE, GIAN ANGELO M. | C29: BSIT-CISCO | D29: 1
A30: 25 | B30: GALLARDO, JAMIE E. | C30: BSIT-CISCO | D30: 1
A31: 26 | B31: PELEGRIN, KEITH BALDWIN I. | C31: BSIT-CISCO | D31: 1
A32: 27 | B32: OCTAVIANO, GEO A. | C32: BSIT-CISCO | D32: 1
A33: 28 | B33: KHU, FRANIJE S. | C33: BSIT-CISCO | D33: 1
A34: 29 | B34: CAGULADA, MARC LORDY B. | C34: BSIT-CISCO | D34: 1
A35: 30 | B35: DIEZ, PRINCESS DOVE P. | C35: BSIT-CISCO | D35: 1
A36: 31 | B36: LLANETA, CESABEL A. | C36: BSIT-CISCO | D36: 1 | E36: 400 | F36: 45799 | G36: CASH | H36: 6
A37: 32 | B37: ENGADA, JOHN FRANCIS S. | C37: BSIT-CISCO | D37: 1
A38: 33 | B38: BRAZIL, RALPH D. | C38: BSIT-CISCO | D38: 1
A39: 34 | B39: SALVAÑA, LAWRENCE VINCENT II B. | C39: BSIT-CISCO | D39: 1 | E39: 400 | F39: 45804 | G39: CASH | H39: 9
A40: 35 | B40: ALAGON, JEYAN N. | C40: BSIT-CISCO | D40: 1
A41: 36 | B41: DELA PEÑA, EMANUEL JOHN S. | C41: BSIT-CISCO | D41: 1
A42: 37 | B42: NAMALATA, JOHN WARREN P. | C42: BSIT-CISCO | D42: 1
A43: 38 | B43: DEE, JAZEL MAY P. | C43: BSIT-CISCO | D43: 1
A44: 39 | B44: PACQUIAO, CHAZY CHAZ T. | C44: BSIT-CISCO | D44: 1
A45: 40 | B45: BACALAN, JONATHAN JR. G. | C45: BSIT-CISCO | D45: 1
...

Sheet AParty
A1: APARTY COLLECTION (279 X 1000 = 278,600)
B3: Collection Amount | C3: =SUM(E6:E284) -> 0 | E3: Account Collectable : | G3: =(279*1000)-C3 -> 279000
A5: SL # | B5: STUDENT NAME | C5: COURSE/Major | D5: YEAR | E5: Amount | F5: Date Paid | G5: Payment Type | H5: OR#
A6: 1 | B6: SACAL, GERELYN KAWE T. | C6: BLIS | D6: 1
A7: 2 | B7: VILELA, SAMANTHA KRIS P. | C7: BLIS | D7: 1
A8: 3 | B8: MORENO, NICOLE ROANNIE D. | C8: BLIS | D8: 1
A9: 4 | B9: YAMSON, HOPE GRACE I. | C9: BLIS | D9: 1
A10: 5 | B10: TEJANO, ERIKA MAE A. | C10: BLIS | D10: 1
A11: 6 | B11: DE-ERIT, ROSE MAE J. | C11: BLIS | D11: 1
A12: 7 | B12: ADAJAR, RHEA JEAN M. | C12: BLIS-ACADEMIC TRACK | D12: 1
A13: 8 | B13: OMANDAM, ANDRE JOSHUA P. | C13: BSIT-CISCO | D13: 1
A14: 9 | B14: MAGBOO, RALPH JOSHUA P. | C14: BSIT-CISCO | D14: 1
A15: 10 | B15: NAVARRO, MIKKO S. | C15: BSIT-CISCO | D15: 1
A16: 11 | B16: CANDIA, SOPHIA CHRISTIANA A. | C16: BSIT-CISCO | D16: 1
A17: 12 | B17: LALA, LANCE NICHOLAS | C17: BSIT-CISCO | D17: 1
... A284: 279 | B284: QUINTILA, MARSH IVAN H. | C284: BSIT-CISCO | D284: 4

Sheet Tshirt
A1: TSHIRT COLLECTION (279 X ??? = ???? )
B3: Collection Amount | C3: =SUM(E5:E283) -> 0 | E3: Account Collectable : | G3: =(279*400)-C3 -> 111600
A4: SL # | B4: STUDENT NAME | C4: COURSE/Major | D4: YEAR | E4: Amount | F4: Date Paid | G4: Payment Type | H4: OR#
A5: 1 | B5: SACAL, GERELYN KAWE T. | C5: BLIS | D5: 1
A6: 2 | B6: VILELA, SAMANTHA KRIS P. | C6: BLIS | D6: 1
A7: 3 | B7: MORENO, NICOLE ROANNIE D. | C7: BLIS | D7: 1
A8: 4 | B8: YAMSON, HOPE GRACE I. | C8: BLIS | D8: 1
A9: 5 | B9: TEJANO, ERIKA MAE A. | C9: BLIS | D9: 1
A10: 6 | B10: DE-ERIT, ROSE MAE J. | C10: BLIS | D10: 1
A11: 7 | B11: ADAJAR, RHEA JEAN M. | C11: BLIS-ACADEMIC TRACK | D11: 1
A12: 8 | B12: OMANDAM, ANDRE JOSHUA P. | C12: BSIT-CISCO | D12: 1
A13: 9 | B13: MAGBOO, RALPH JOSHUA P. | C13: BSIT-CISCO | D13: 1
A14: 10 | B14: NAVARRO, MIKKO S. | C14: BSIT-CISCO | D14: 1
A15: 11 | B15: CANDIA, SOPHIA CHRISTIANA A. | C15: BSIT-CISCO | D15: 1
A16: 12 | B16: LALA, LANCE NICHOLAS | C16: BSIT-CISCO | D16: 1
... A64: 60 | B64: GARAY, JOHN ROLAND H. | C64: BSIT-CISCO | D64: 1
A65: 61 | B65: GUMERA, JOSHUA ALBERT S. | C65: BSIT-CISCO | D65: 1 | G65: GCASH
A66: 62 | B66: BULAWIN, CAVHEN JOSHUA C. | C66: BSIT-CISCO | D66: 1
A67: 63 | B67: BADA, KENNETH TROY C. | C67: BSIT-CISCO | D67: 1
A68: 64 | B68: NAVARRO, KEITH RUSSELLE N. | C68: BSIT-CISCO | D68: 1
A69: 65 | B69: ACANTILADO, DENNIS C. | C69: BSIT-CISCO | D69: 1
A70: 66 | B70: COCAMAS, ADONIS JR. O. | C70: BSIT-CISCO | D70: 1
A71: 67 | B71: REDOSENDO, RALPH ETHAN M. | C71: BSIT-CISCO | D71: 1
A72: 68 | B72: CABALIDA, JOHN ALFERD O. | C72: BSIT-CISCO | D72: 1
A73: 69 | B73: SUELA, KYLE DANIEL D. | C73: BSIT-CISCO | D73: 1
A74: 70 | B74: ZAMBAS, MARY FAITH U. | C74: BSIT-CISCO | D74: 1
A75: 71 | B75: YECYEC, HELLEIBREY D.C. | C75: BSIT-CISCO | D75: 1
A76: 72 | B76: ISMA, EARL JOHN S. | C76: BSIT-CISCO | D76: 1
A77: 73 | B77: ALLONES, RENDON M. | C77: BSIT-CISCO | D77: 1
... A283: 279 | B283: QUINTILA, MARSH IVAN H. | C283: BSIT-CISCO | D283: 4

Sheet Intrams
A1: INTRAMURALS COLLECTION (279 x ????? = ????)
B3: Collection Amount | C3: =SUM(E5:E283) -> 0 | E3: Account Collectable : | G3: ????
A4: SL # | B4: STUDENT NAME | C4: COURSE/Major | D4: YEAR | E4: Amount | F4: Date Paid | G4: Payment Type | H4: OR#
A5: 1 | B5: SACAL, GERELYN KAWE T. | C5: BLIS | D5: 1
A6: 2 | B6: VILELA, SAMANTHA KRIS P. | C6: BLIS | D6: 1
A7: 3 | B7: MORENO, NICOLE ROANNIE D. | C7: BLIS | D7: 1
A8: 4 | B8: YAMSON, HOPE GRACE I. | C8: BLIS | D8: 1
A9: 5 | B9: TEJANO, ERIKA MAE A. | C9: BLIS | D9: 1
A10: 6 | B10: DE-ERIT, ROSE MAE J. | C10: BLIS | D10: 1
A11: 7 | B11: ADAJAR, RHEA JEAN M. | C11: BLIS-ACADEMIC TRACK | D11: 1
A12: 8 | B12: OMANDAM, ANDRE JOSHUA P. | C12: BSIT-CISCO | D12: 1
A13: 9 | B13: MAGBOO, RALPH JOSHUA P. | C13: BSIT-CISCO | D13: 1
A14: 10 | B14: NAVARRO, MIKKO S. | C14: BSIT-CISCO | D14: 1
A15: 11 | B15: CANDIA, SOPHIA CHRISTIANA A. | C15: BSIT-CISCO | D15: 1
A16: 12 | B16: LALA, LANCE NICHOLAS | C16: BSIT-CISCO | D16: 1
... A283: 279 | B283: QUINTILA, MARSH IVAN H. | C283: BSIT-CISCO | D283: 4

Sheet Fines
A1: SBO FEE COLLECTION (279 X 400 = 111,600)
B3: Collection Amount | C3: =SUM(E5:E283) -> 108000 | E3: Account Collectable : | J3: =(279*400)-C3 -> 3600
A4: SL # | B4: STUDENT NAME | D4: YEAR | E4: SBO | F4: AParty | G4: Tshirt | H4: Intrams | I4: Attendance | J4: Payment Type | K4: OR#
A5: 1 | B5: SACAL, GERELYN KAWE T. | C5: BLIS | D5: 1 | E5: =if(SBO!E7=400,0,400) -> 400
A6: 2 | B6: VILELA, SAMANTHA KRIS P. | C6: BLIS | D6: 1 | E6: =if(SBO!E8=400,0,400) -> 400
A7: 3 | B7: MORENO, NICOLE ROANNIE D. | C7: BLIS | D7: 1 | E7: =if(SBO!E9=400,0,400) -> 400
A8: 4 | B8: YAMSON, HOPE GRACE I. | C8: BLIS | D8: 1 | E8: =if(SBO!E10=400,0,400) -> 400
A9: 5 | B9: TEJANO, ERIKA MAE A. | C9: BLIS | D9: 1 | E9: =if(SBO!E11=400,0,400) -> 400
A10: 6 | B10: DE-ERIT, ROSE MAE J. | C10: BLIS | D10: 1 | E10: =if(SBO!E12=400,0,400) -> 400
A11: 7 | B11: ADAJAR, RHEA JEAN M. | C11: BLIS-ACADEMIC TRACK | D11: 1 | E11: =if(SBO!E13=400,0,400) -> 400
A12: 8 | B12: OMANDAM, ANDRE JOSHUA P. | C12: BSIT-CISCO | D12: 1 | E12: =if(SBO!E14=400,0,400) -> 400
A13: 9 | B13: MAGBOO, RALPH JOSHUA P. | C13: BSIT-CISCO | D13: 1 | E13: =if(SBO!E15=400,0,400) -> 400
A14: 10 | B14: NAVARRO, MIKKO S. | C14: BSIT-CISCO | D14: 1 | E14: =if(SBO!E16=400,0,400) -> 400
A15: 11 | B15: CANDIA, SOPHIA CHRISTIANA A. | C15: BSIT-CISCO | D15: 1 | E15: =if(SBO!E17=400,0,400) -> 400
A16: 12 | B16: LALA, LANCE NICHOLAS | C16: BSIT-CISCO | D16: 1 | E16: =if(SBO!E18=400,0,400) -> 400
... A20: 16 | B20: Acero, James B. | C20: BSIT-CISCO | D20: 1 | E20: =if(SBO!E22=400,0,400) -> 0
A21: 17 | B21: Nabos, Mariane T. | C21: BSIT-CISCO | D21: 1 | E21: =if(SBO!E23=400,0,400) -> 400 | J21: CASH
A22: 18 | B22: MALAYA, JHOZEL M. | C22: BSIT-CISCO | D22: 1 | E22: =if(SBO!E24=400,0,400) -> 400
A23: 19 | B23: CAGALITAN, ALLYXZA SOPHIA K. | C23: BSIT-CISCO | D23: 1 | E23: =if(SBO!E25=400,0,400) -> 400
A24: 20 | B24: UBA, KEN MARK C. | C24: BSIT-CISCO | D24: 1 | E24: =if(SBO!E26=400,0,400) -> 400
A25: 21 | B25: BALATAYO, FREDERICK JAMES S. | C25: BSIT-CISCO | D25: 1 | E25: =if(SBO!E27=400,0,400) -> 400
A26: 22 | B26: VALDEZ, PRINCESS MARIE J. | C26: BSIT-CISCO | D26: 1 | E26: =if(SBO!E28=400,0,400) -> 400
A27: 23 | B27: MAGUIDALA, CARIM S. | C27: BSIT-CISCO | D27: 1 | E27: =if(SBO!E29=400,0,400) -> 400
A28: 24 | B28: AGUE, GIAN ANGELO M. | C28: BSIT-CISCO | D28: 1 | E28: =if(SBO!E30=400,0,400) -> 400
A29: 25 | B29: GALLARDO, JAMIE E. | C29: BSIT-CISCO | D29: 1 | E29: =if(SBO!E31=400,0,400) -> 400
A30: 26 | B30: PELEGRIN, KEITH BALDWIN I. | C30: BSIT-CISCO | D30: 1 | E30: =if(SBO!E32=400,0,400) -> 400
A31: 27 | B31: OCTAVIANO, GEO A. | C31: BSIT-CISCO | D31: 1 | E31: =if(SBO!E33=400,0,400) -> 400
A32: 28 | B32: KHU, FRANIJE S. | C32: BSIT-CISCO | D32: 1 | E32: =if(SBO!E34=400,0,400) -> 400
A33: 29 | B33: CAGULADA, MARC LORDY B. | C33: BSIT-CISCO | D33: 1 | E33: =if(SBO!E35=400,0,400) -> 400
... A64: 60 | B64: GARAY, JOHN ROLAND H. | C64: BSIT-CISCO | D64: 1 | E64: =if(SBO!E66=400,0,400) -> 0
A65: 61 | B65: GUMERA, JOSHUA ALBERT S. | C65: BSIT-CISCO | D65: 1 | E65: =if(SBO!E67=400,0,400) -> 0 | J65: CASH
A66: 62 | B66: BULAWIN, CAVHEN JOSHUA C. | C66: BSIT-CISCO | D66: 1 | E66: =if(SBO!E68=400,0,400) -> 0 | J66: CASH
A67: 63 | B67: BADA, KENNETH TROY C. | C67: BSIT-CISCO | D67: 1 | E67: =if(SBO!E69=400,0,400) -> 400 | J67: CASH
A68: 64 | B68: NAVARRO, KEITH RUSSELLE N. | C68: BSIT-CISCO | D68: 1 | E68: =if(SBO!E70=400,0,400) -> 400
A69: 65 | B69: ACANTILADO, DENNIS C. | C69: BSIT-CISCO | D69: 1 | E69: =if(SBO!E71=400,0,400) -> 0
A70: 66 | B70: COCAMAS, ADONIS JR. O. | C70: BSIT-CISCO | D70: 1 | E70: =if(SBO!E72=400,0,400) -> 400
A71: 67 | B71: REDOSENDO, RALPH ETHAN M. | C71: BSIT-CISCO | D71: 1 | E71: =if(SBO!E73=400,0,400) -> 400
A72: 68 | B72: CABALIDA, JOHN ALFERD O. | C72: BSIT-CISCO | D72: 1 | E72: =if(SBO!E74=400,0,400) -> 0
A73: 69 | B73: SUELA, KYLE DANIEL D. | C73: BSIT-CISCO | D73: 1 | E73: =if(SBO!E75=400,0,400) -> 400
A74: 70 | B74: ZAMBAS, MARY FAITH U. | C74: BSIT-CISCO | D74: 1 | E74: =if(SBO!E76=400,0,400) -> 400
...
